<?xml version="1.0" encoding="utf-8"?>
<!-- =================================================================================== -->
<!-- |    This document was autogenerated by xacro from urdf/dk1.xacro                 | -->
<!-- |    EDITING THIS FILE BY HAND IS NOT RECOMMENDED                                 | -->
<!-- =================================================================================== -->
<!-- Revolute-Revolute Manipulator -->
<robot name="dk1">
  <!-- Switch between airgaiting or standing on the ground-->
  <!--Value set to: 'world' fixes the robot to the world-->
  <!--Value set to: 'base_link' makes the robot stand on the ground-->
  <!--Important note: when changing value make sure rviz fixed frame is set to the same value (moveit.rviz)-->
  <!-- Cube dimensions (width x width x width) of joint base -->
  <!-- rad/s -->
  <!-- Used for fixing robot to Gazebo 'base_link' -->
  <link name="world"/>
  <joint name="joint_base_fixed_parent_joint" type="fixed">
    <parent link="world"/>
    <child link="joint_base"/>
    <origin rpy="0 0 0" xyz="0 0 0.5"/>
  </joint>
  <joint name="linear_joint" type="revolute">
    <parent link="joint_base"/>
    <child link="bar"/>
    <origin rpy="0 0 0" xyz="0 -0.05 0"/>
    <axis xyz="0 1 0"/>
  </joint>
  <!-- Joint Base-->
  <link name="joint_base">
    <visual>
      <origin rpy="0 0 0" xyz="0 0 0"/>
      <geometry>
        <box size="0.05 0.05 0.05"/>
      </geometry>
    </visual>
    <inertial>
      <origin rpy="0 0 0" xyz="0 0 0"/>
      <mass value="1"/>
      <inertia ixx="0.000416666666667" ixy="0.0" ixz="0.0" iyy="0.000416666666667" iyz="0.0" izz="0.000416666666667"/>
      <!--(joint_base_width*joint_base_width + joint_base_width*joint_base_width)-->
    </inertial>
  </link>
  <!-- Bar-->
  <link name="bar">
    <visual>
      <origin rpy="0 0 0" xyz="0 0 -0.195"/>
      <geometry>
        <box size="0.05 0.05 0.39"/>
      </geometry>
    </visual>
    <inertial>
      <origin rpy="0 0 0" xyz="0 0 -0.195"/>
      <mass value="1.08"/>
      <inertia ixx="0.0128833333333" ixy="0.0" ixz="0.0" iyy="0.0128833333333" iyz="0.0" izz="0.000416666666667"/>
    </inertial>
  </link>
</robot>
